[2024-10-14T17:30:20.163+0000] {local_task_job_runner.py:123} INFO - ::group::Pre task execution logs
[2024-10-14T17:30:23.808+0000] {taskinstance.py:2612} INFO - Dependencies all met for dep_context=non-requeueable deps ti=<TaskInstance: dag_ccl.ccl_to_redshift manual__2024-10-14T17:30:04.943076+00:00 [queued]>
[2024-10-14T17:30:24.253+0000] {taskinstance.py:2612} INFO - Dependencies all met for dep_context=requeueable deps ti=<TaskInstance: dag_ccl.ccl_to_redshift manual__2024-10-14T17:30:04.943076+00:00 [queued]>
[2024-10-14T17:30:24.282+0000] {taskinstance.py:2865} INFO - Starting attempt 1 of 2
[2024-10-14T17:30:26.662+0000] {taskinstance.py:2888} INFO - Executing <Task(PythonOperator): ccl_to_redshift> on 2024-10-14 17:30:04.943076+00:00
[2024-10-14T17:30:27.294+0000] {warnings.py:112} WARNING - /home/***/.local/lib/python3.12/site-packages/***/task/task_runner/standard_task_runner.py:70: DeprecationWarning: This process (pid=19076) is multi-threaded, use of fork() may lead to deadlocks in the child.
  pid = os.fork()

[2024-10-14T17:30:27.329+0000] {standard_task_runner.py:72} INFO - Started process 19113 to run task
[2024-10-14T17:30:29.076+0000] {standard_task_runner.py:104} INFO - Running: ['***', 'tasks', 'run', 'dag_ccl', 'ccl_to_redshift', 'manual__2024-10-14T17:30:04.943076+00:00', '--job-id', '287', '--raw', '--subdir', 'DAGS_FOLDER/dag_ccl.py', '--cfg-path', '/tmp/tmperi0aqnu']
[2024-10-14T17:30:31.251+0000] {standard_task_runner.py:105} INFO - Job 287: Subtask ccl_to_redshift
[2024-10-14T17:30:34.289+0000] {task_command.py:467} INFO - Running <TaskInstance: dag_ccl.ccl_to_redshift manual__2024-10-14T17:30:04.943076+00:00 [running]> on host f03003374728
[2024-10-14T17:30:37.767+0000] {job.py:229} INFO - Heartbeat recovered after 20.68 seconds
[2024-10-14T17:31:03.734+0000] {job.py:229} INFO - Heartbeat recovered after 10.93 seconds
[2024-10-14T17:31:22.103+0000] {job.py:229} INFO - Heartbeat recovered after 18.64 seconds
[2024-10-14T17:31:42.248+0000] {job.py:229} INFO - Heartbeat recovered after 23.50 seconds
[2024-10-14T17:31:53.571+0000] {job.py:229} INFO - Heartbeat recovered after 12.15 seconds
[2024-10-14T17:32:07.683+0000] {job.py:229} INFO - Heartbeat recovered after 14.29 seconds
[2024-10-14T17:32:20.957+0000] {job.py:229} INFO - Heartbeat recovered after 16.28 seconds
[2024-10-14T17:32:34.383+0000] {job.py:229} INFO - Heartbeat recovered after 15.19 seconds
[2024-10-14T17:32:49.524+0000] {job.py:229} INFO - Heartbeat recovered after 18.38 seconds
[2024-10-14T17:33:04.726+0000] {job.py:229} INFO - Heartbeat recovered after 15.64 seconds
[2024-10-14T17:33:15.171+0000] {local_task_job_runner.py:346} WARNING - State of this instance has been externally set to failed. Terminating instance.
[2024-10-14T17:33:15.341+0000] {local_task_job_runner.py:245} INFO - ::endgroup::
[2024-10-14T17:33:15.787+0000] {process_utils.py:132} INFO - Sending 15 to group 19113. PIDs of all processes in the group: [19113]
[2024-10-14T17:33:15.885+0000] {process_utils.py:87} INFO - Sending the signal 15 to group 19113
[2024-10-14T17:33:16.019+0000] {taskinstance.py:3092} ERROR - Received SIGTERM. Terminating subprocesses.
[2024-10-14T17:33:22.198+0000] {taskinstance.py:340} INFO - ::group::Post task execution logs
[2024-10-14T17:33:25.414+0000] {process_utils.py:80} INFO - Process psutil.Process(pid=19113, status='terminated', exitcode=0, started='17:30:26') (19113) terminated with exit code 0
