[2024-10-06T18:12:37.607+0000] {local_task_job_runner.py:123} INFO - ::group::Pre task execution logs
[2024-10-06T18:12:37.644+0000] {taskinstance.py:2612} INFO - Dependencies all met for dep_context=non-requeueable deps ti=<TaskInstance: dag_cargar_cotizaciones.obtener_y_preparar_cotizaciones scheduled__2024-09-16T00:00:00+00:00 [queued]>
[2024-10-06T18:12:37.655+0000] {taskinstance.py:2612} INFO - Dependencies all met for dep_context=requeueable deps ti=<TaskInstance: dag_cargar_cotizaciones.obtener_y_preparar_cotizaciones scheduled__2024-09-16T00:00:00+00:00 [queued]>
[2024-10-06T18:12:37.661+0000] {taskinstance.py:2865} INFO - Starting attempt 2 of 2
[2024-10-06T18:12:37.697+0000] {taskinstance.py:2888} INFO - Executing <Task(PythonOperator): obtener_y_preparar_cotizaciones> on 2024-09-16 00:00:00+00:00
[2024-10-06T18:12:37.733+0000] {warnings.py:112} WARNING - /home/***/.local/lib/python3.12/site-packages/***/task/task_runner/standard_task_runner.py:70: DeprecationWarning: This process (pid=636) is multi-threaded, use of fork() may lead to deadlocks in the child.
  pid = os.fork()

[2024-10-06T18:12:37.744+0000] {standard_task_runner.py:72} INFO - Started process 654 to run task
[2024-10-06T18:12:37.740+0000] {standard_task_runner.py:104} INFO - Running: ['***', 'tasks', 'run', 'dag_cargar_cotizaciones', 'obtener_y_preparar_cotizaciones', 'scheduled__2024-09-16T00:00:00+00:00', '--job-id', '32', '--raw', '--subdir', 'DAGS_FOLDER/dag_cargar_cotizaciones.py', '--cfg-path', '/tmp/tmph9z2uqx2']
[2024-10-06T18:12:37.749+0000] {standard_task_runner.py:105} INFO - Job 32: Subtask obtener_y_preparar_cotizaciones
[2024-10-06T18:12:37.853+0000] {task_command.py:467} INFO - Running <TaskInstance: dag_cargar_cotizaciones.obtener_y_preparar_cotizaciones scheduled__2024-09-16T00:00:00+00:00 [running]> on host f03003374728
[2024-10-06T18:12:38.078+0000] {taskinstance.py:3131} INFO - Exporting env vars: AIRFLOW_CTX_DAG_OWNER='***' AIRFLOW_CTX_DAG_ID='dag_cargar_cotizaciones' AIRFLOW_CTX_TASK_ID='obtener_y_preparar_cotizaciones' AIRFLOW_CTX_EXECUTION_DATE='2024-09-16T00:00:00+00:00' AIRFLOW_CTX_TRY_NUMBER='2' AIRFLOW_CTX_DAG_RUN_ID='scheduled__2024-09-16T00:00:00+00:00'
[2024-10-06T18:12:38.080+0000] {taskinstance.py:731} INFO - ::endgroup::
[2024-10-06T18:12:38.119+0000] {base.py:84} INFO - Retrieving connection 'redshift_conn'
[2024-10-06T18:12:38.123+0000] {taskinstance.py:3310} ERROR - Task failed with exception
Traceback (most recent call last):
  File "/home/airflow/.local/lib/python3.12/site-packages/airflow/models/taskinstance.py", line 767, in _execute_task
    result = _execute_callable(context=context, **execute_callable_kwargs)
             ^^^^^^^^^^^^^^^^^^^^^^^^^^^^^^^^^^^^^^^^^^^^^^^^^^^^^^^^^^^^^
  File "/home/airflow/.local/lib/python3.12/site-packages/airflow/models/taskinstance.py", line 733, in _execute_callable
    return ExecutionCallableRunner(
           ^^^^^^^^^^^^^^^^^^^^^^^^
  File "/home/airflow/.local/lib/python3.12/site-packages/airflow/utils/operator_helpers.py", line 252, in run
    return self.func(*args, **kwargs)
           ^^^^^^^^^^^^^^^^^^^^^^^^^^
  File "/home/airflow/.local/lib/python3.12/site-packages/airflow/models/baseoperator.py", line 406, in wrapper
    return func(self, *args, **kwargs)
           ^^^^^^^^^^^^^^^^^^^^^^^^^^^
  File "/home/airflow/.local/lib/python3.12/site-packages/airflow/operators/python.py", line 238, in execute
    return_value = self.execute_callable()
                   ^^^^^^^^^^^^^^^^^^^^^^^
  File "/home/airflow/.local/lib/python3.12/site-packages/airflow/operators/python.py", line 256, in execute_callable
    return runner.run(*self.op_args, **self.op_kwargs)
           ^^^^^^^^^^^^^^^^^^^^^^^^^^^^^^^^^^^^^^^^^^^
  File "/home/airflow/.local/lib/python3.12/site-packages/airflow/utils/operator_helpers.py", line 252, in run
    return self.func(*args, **kwargs)
           ^^^^^^^^^^^^^^^^^^^^^^^^^^
  File "/opt/airflow/dags/load_data_to_redshift.py", line 11, in load_data_to_redshift
    start_date=context['data_interval_start']
              ^^^^^^^
NameError: name 'context' is not defined
[2024-10-06T18:12:38.141+0000] {taskinstance.py:1225} INFO - Marking task as FAILED. dag_id=dag_cargar_cotizaciones, task_id=obtener_y_preparar_cotizaciones, run_id=scheduled__2024-09-16T00:00:00+00:00, execution_date=20240916T000000, start_date=20241006T181237, end_date=20241006T181238
[2024-10-06T18:12:38.151+0000] {taskinstance.py:340} INFO - ::group::Post task execution logs
[2024-10-06T18:12:38.152+0000] {standard_task_runner.py:124} ERROR - Failed to execute job 32 for task obtener_y_preparar_cotizaciones (name 'context' is not defined; 654)
Traceback (most recent call last):
  File "/home/airflow/.local/lib/python3.12/site-packages/airflow/task/task_runner/standard_task_runner.py", line 117, in _start_by_fork
    ret = args.func(args, dag=self.dag)
          ^^^^^^^^^^^^^^^^^^^^^^^^^^^^^
  File "/home/airflow/.local/lib/python3.12/site-packages/airflow/cli/cli_config.py", line 49, in command
    return func(*args, **kwargs)
           ^^^^^^^^^^^^^^^^^^^^^
  File "/home/airflow/.local/lib/python3.12/site-packages/airflow/utils/cli.py", line 115, in wrapper
    return f(*args, **kwargs)
           ^^^^^^^^^^^^^^^^^^
  File "/home/airflow/.local/lib/python3.12/site-packages/airflow/cli/commands/task_command.py", line 483, in task_run
    task_return_code = _run_task_by_selected_method(args, _dag, ti)
                       ^^^^^^^^^^^^^^^^^^^^^^^^^^^^^^^^^^^^^^^^^^^^
  File "/home/airflow/.local/lib/python3.12/site-packages/airflow/cli/commands/task_command.py", line 256, in _run_task_by_selected_method
    return _run_raw_task(args, ti)
           ^^^^^^^^^^^^^^^^^^^^^^^
  File "/home/airflow/.local/lib/python3.12/site-packages/airflow/cli/commands/task_command.py", line 341, in _run_raw_task
    return ti._run_raw_task(
           ^^^^^^^^^^^^^^^^^
  File "/home/airflow/.local/lib/python3.12/site-packages/airflow/utils/session.py", line 97, in wrapper
    return func(*args, session=session, **kwargs)
           ^^^^^^^^^^^^^^^^^^^^^^^^^^^^^^^^^^^^^^
  File "/home/airflow/.local/lib/python3.12/site-packages/airflow/models/taskinstance.py", line 3004, in _run_raw_task
    return _run_raw_task(
           ^^^^^^^^^^^^^^
  File "/home/airflow/.local/lib/python3.12/site-packages/airflow/models/taskinstance.py", line 273, in _run_raw_task
    TaskInstance._execute_task_with_callbacks(
  File "/home/airflow/.local/lib/python3.12/site-packages/airflow/models/taskinstance.py", line 3158, in _execute_task_with_callbacks
    result = self._execute_task(context, task_orig)
             ^^^^^^^^^^^^^^^^^^^^^^^^^^^^^^^^^^^^^^
  File "/home/airflow/.local/lib/python3.12/site-packages/airflow/models/taskinstance.py", line 3182, in _execute_task
    return _execute_task(self, context, task_orig)
           ^^^^^^^^^^^^^^^^^^^^^^^^^^^^^^^^^^^^^^^
  File "/home/airflow/.local/lib/python3.12/site-packages/airflow/models/taskinstance.py", line 767, in _execute_task
    result = _execute_callable(context=context, **execute_callable_kwargs)
             ^^^^^^^^^^^^^^^^^^^^^^^^^^^^^^^^^^^^^^^^^^^^^^^^^^^^^^^^^^^^^
  File "/home/airflow/.local/lib/python3.12/site-packages/airflow/models/taskinstance.py", line 733, in _execute_callable
    return ExecutionCallableRunner(
           ^^^^^^^^^^^^^^^^^^^^^^^^
  File "/home/airflow/.local/lib/python3.12/site-packages/airflow/utils/operator_helpers.py", line 252, in run
    return self.func(*args, **kwargs)
           ^^^^^^^^^^^^^^^^^^^^^^^^^^
  File "/home/airflow/.local/lib/python3.12/site-packages/airflow/models/baseoperator.py", line 406, in wrapper
    return func(self, *args, **kwargs)
           ^^^^^^^^^^^^^^^^^^^^^^^^^^^
  File "/home/airflow/.local/lib/python3.12/site-packages/airflow/operators/python.py", line 238, in execute
    return_value = self.execute_callable()
                   ^^^^^^^^^^^^^^^^^^^^^^^
  File "/home/airflow/.local/lib/python3.12/site-packages/airflow/operators/python.py", line 256, in execute_callable
    return runner.run(*self.op_args, **self.op_kwargs)
           ^^^^^^^^^^^^^^^^^^^^^^^^^^^^^^^^^^^^^^^^^^^
  File "/home/airflow/.local/lib/python3.12/site-packages/airflow/utils/operator_helpers.py", line 252, in run
    return self.func(*args, **kwargs)
           ^^^^^^^^^^^^^^^^^^^^^^^^^^
  File "/opt/airflow/dags/load_data_to_redshift.py", line 11, in load_data_to_redshift
    start_date=context['data_interval_start']
              ^^^^^^^
NameError: name 'context' is not defined
[2024-10-06T18:12:38.184+0000] {local_task_job_runner.py:266} INFO - Task exited with return code 1
[2024-10-06T18:12:38.198+0000] {taskinstance.py:3900} INFO - 0 downstream tasks scheduled from follow-on schedule check
[2024-10-06T18:12:38.199+0000] {local_task_job_runner.py:245} INFO - ::endgroup::
